Workbook

Sheet Paramètres
A1: ⚽ FIVEUR ACADEMY — Since 2023
A2: Mauritanie — Paramètres & Tarifs
A4: TARIFS FOOTBALL (mensuel)
A5: Catégorie | B5: Âge min | C5: Âge max | D5: Tarif (MRU)
A6: U5 | B6: 3 | C6: 5 | D6: 2500
A7: U7 | B7: 5 | C7: 7 | D7: 3000
A8: U9 | B8: 7 | C8: 9 | D8: 3500
A9: U11 | B9: 9 | C9: 11 | D9: 4000
A10: U12F | B10: 10 | C10: 12 | D10: 4000
A11: U13 | B11: 11 | C11: 13 | D11: 4500
A12: U15 | B12: 13 | C12: 15 | D12: 5000
A13: U15F | B13: 13 | C13: 15 | D13: 5000
A16: TARIF CENTRE DE LOISIRS (mensuel)
A17: Centre de Loisirs | B17: Tous âges | D17: 2500
A19: FORMULE COMBINÉE (Football + Loisirs)
A20: Réduction combo (%) | D20: 0.2

Sheet Inscriptions
A1: 📋 FIVEUR ACADEMY — REGISTRE DES INSCRIPTIONS
A2: N° | B2: Nom | C2: Prénom | D2: Date de naissance | E2: Âge | F2: Sexe | G2: Téléphone Parent | H2: Adresse | I2: Football | J2: Centre Loisirs | K2: Catégorie Foot | L2: Tarif Football | M2: Tarif Loisirs | N2: Tarif Total | O2: Statut Paiement | P2: Date Paiement | Q2: Observations | R2: Date Limite Paiement | S2: Retard (jours) | T2: Statut Délai
A3: 1 | B3: SIDIBÉ | C3: Younous | D3: 43271 | E3: =IF(D3="","",DATEDIF(D3,TODAY(),"Y")) -> 7 | F3: M | G3: +222 49 83 01 84 | H3: BASRA | I3: Oui | J3: Non | K3: =IF(I3<>"Oui","",IF(E3="","",IF(E3<5,"U5",IF(E3<7,"U7",IF(E3<9,"U9",IF(E3<10,"U11",IF(F3="F",IF(E3<12,"U12F","U15F"),IF(E3<11,"U11",IF(E3<13,"U13","U15"))))))))) -> U9 | L3: 1750 | N3: =IF(AND(I3="Oui",J3="Oui"),(L3+M3)*(1-Paramètres!$D$20),L3+M3) -> 1750 | O3: Payé | P3: 46122 | Q3: Manque identité | S3: =IF(OR(B3="",R3="",O3="Payé"),"",MAX(0,TODAY()-R3)) | T3: =IF(B3="","",IF(O3="Payé","✅ À jour",IF(R3="","⏳ Pas de date",IF(TODAY()>R3,"🔴 En retard",IF(R3-TODAY()<=7,"🟡 Bientôt dû","🟢 Dans les temps"))))) -> ✅ À jour
A4: 2 | B4: SIDIBÉ | C4: Zackaria | D4: 42394 | E4: =IF(D4="","",DATEDIF(D4,TODAY(),"Y")) -> 10 | F4: M | G4: +222 49 83 01 84 | H4: BASRA | I4: Oui | J4: Non | K4: =IF(I4<>"Oui","",IF(E4="","",IF(E4<5,"U5",IF(E4<7,"U7",IF(E4<9,"U9",IF(E4<10,"U11",IF(F4="F",IF(E4<12,"U12F","U15F"),IF(E4<11,"U11",IF(E4<13,"U13","U15"))))))))) -> U11 | L4: 1750 | N4: =IF(AND(I4="Oui",J4="Oui"),(L4+M4)*(1-Paramètres!$D$20),L4+M4) -> 1750 | O4: Payé | P4: 46122 | Q4: Manque identité | R4: 46096 | S4: =IF(OR(B4="",R4="",O4="Payé"),"",MAX(0,TODAY()-R4)) | T4: =IF(B4="","",IF(O4="Payé","✅ À jour",IF(R4="","⏳ Pas de date",IF(TODAY()>R4,"🔴 En retard",IF(R4-TODAY()<=7,"🟡 Bientôt dû","🟢 Dans les temps"))))) -> ✅ À jour
A5: 3 | B5: DIALLO | C5: Youssouf | D5: 42071 | E5: =IF(D5="","",DATEDIF(D5,TODAY(),"Y")) -> 11 | F5: M | G5: +222 48 44 07 94 | H5: ILOT L | I5: Oui | J5: Non | K5: =IF(I5<>"Oui","",IF(E5="","",IF(E5<5,"U5",IF(E5<7,"U7",IF(E5<9,"U9",IF(E5<10,"U11",IF(F5="F",IF(E5<12,"U12F","U15F"),IF(E5<11,"U11",IF(E5<13,"U13","U15"))))))))) -> U13 | L5: 2000 | N5: =IF(AND(I5="Oui",J5="Oui"),(L5+M5)*(1-Paramètres!$D$20),L5+M5) -> 2000 | O5: Payé | P5: 46122 | Q5: manque photo | R5: 46142 | S5: =IF(OR(B5="",R5="",O5="Payé"),"",MAX(0,TODAY()-R5)) | T5: =IF(B5="","",IF(O5="Payé","✅ À jour",IF(R5="","⏳ Pas de date",IF(TODAY()>R5,"🔴 En retard",IF(R5-TODAY()<=7,"🟡 Bientôt dû","🟢 Dans les temps"))))) -> ✅ À jour
A6: 4 | B6: THIAM | C6: Mohamed | D6: 42138 | E6: =IF(D6="","",DATEDIF(D6,TODAY(),"Y")) -> 10 | F6: M | G6: +222 41 53 98 46 | H6: CITÉ PLAGE | I6: Oui | J6: Non | K6: =IF(I6<>"Oui","",IF(E6="","",IF(E6<5,"U5",IF(E6<7,"U7",IF(E6<9,"U9",IF(E6<10,"U11",IF(F6="F",IF(E6<12,"U12F","U15F"),IF(E6<11,"U11",IF(E6<13,"U13","U15"))))))))) -> U11 | L6: 1000 | N6: =IF(AND(I6="Oui",J6="Oui"),(L6+M6)*(1-Paramètres!$D$20),L6+M6) -> 1000 | O6: Partiel | P6: 46119 | Q6: manque piece payé bankly | R6: 46117 | S6: =IF(OR(B6="",R6="",O6="Payé"),"",MAX(0,TODAY()-R6)) -> 27 | T6: =IF(B6="","",IF(O6="Payé","✅ À jour",IF(R6="","⏳ Pas de date",IF(TODAY()>R6,"🔴 En retard",IF(R6-TODAY()<=7,"🟡 Bientôt dû","🟢 Dans les temps"))))) -> 🔴 En retard
A7: 5 | B7: THIAM | C7: Adama | D7: 43781 | E7: =IF(D7="","",DATEDIF(D7,TODAY(),"Y")) -> 6 | F7: M | G7: +222 44 89 92 74 | H7: KOSSOVA RYAD | I7: Oui | J7: Non | K7: =IF(I7<>"Oui","",IF(E7="","",IF(E7<5,"U5",IF(E7<7,"U7",IF(E7<9,"U9",IF(E7<10,"U11",IF(F7="F",IF(E7<12,"U12F","U15F"),IF(E7<11,"U11",IF(E7<13,"U13","U15"))))))))) -> U7 | L7: 1000 | N7: =IF(AND(I7="Oui",J7="Oui"),(L7+M7)*(1-Paramètres!$D$20),L7+M7) -> 1000 | O7: Partiel | P7: 46119 | Q7: complet | S7: =IF(OR(B7="",R7="",O7="Payé"),"",MAX(0,TODAY()-R7)) | T7: =IF(B7="","",IF(O7="Payé","✅ À jour",IF(R7="","⏳ Pas de date",IF(TODAY()>R7,"🔴 En retard",IF(R7-TODAY()<=7,"🟡 Bientôt dû","🟢 Dans les temps"))))) -> ⏳ Pas de date
A8: 6 | B8: KOITA | C8: Mohamed | D8: 42802 | E8: =IF(D8="","",DATEDIF(D8,TODAY(),"Y")) -> 9 | F8: M | G8: +222 46 46 65 50 | H8: CITÉ PLAGE | I8: Oui | J8: Non | K8: =IF(I8<>"Oui","",IF(E8="","",IF(E8<5,"U5",IF(E8<7,"U7",IF(E8<9,"U9",IF(E8<10,"U11",IF(F8="F",IF(E8<12,"U12F","U15F"),IF(E8<11,"U11",IF(E8<13,"U13","U15"))))))))) -> U11 | L8: 1000 | O8: Partiel | P8: 46127 | S8: =IF(OR(B8="",R8="",O8="Payé"),"",MAX(0,TODAY()-R8)) | T8: =IF(B8="","",IF(O8="Payé","✅ À jour",IF(R8="","⏳ Pas de date",IF(TODAY()>R8,"🔴 En retard",IF(R8-TODAY()<=7,"🟡 Bientôt dû","🟢 Dans les temps"))))) -> ⏳ Pas de date
A9: 7 | B9: KOITA | C9: Youba | D9: 43340 | E9: =IF(D9="","",DATEDIF(D9,TODAY(),"Y")) -> 7 | F9: M | G9: +222 46 46 65 50 | H9: CITÉ PLAGE | I9: Oui | J9: Non | K9: =IF(I9<>"Oui","",IF(E9="","",IF(E9<5,"U5",IF(E9<7,"U7",IF(E9<9,"U9",IF(E9<10,"U11",IF(F9="F",IF(E9<12,"U12F","U15F"),IF(E9<11,"U11",IF(E9<13,"U13","U15"))))))))) -> U9 | L9: 1000 | O9: Partiel | P9: 46127 | S9: =IF(OR(B9="",R9="",O9="Payé"),"",MAX(0,TODAY()-R9)) | T9: =IF(B9="","",IF(O9="Payé","✅ À jour",IF(R9="","⏳ Pas de date",IF(TODAY()>R9,"🔴 En retard",IF(R9-TODAY()<=7,"🟡 Bientôt dû","🟢 Dans les temps"))))) -> ⏳ Pas de date
A10: 8 | B10: THIAM | C10: Binta | D10: 43426 | E10: =IF(D10="","",DATEDIF(D10,TODAY(),"Y")) -> 7 | F10: F | G10: +222 41 53 98 46 | H10: CITÉ PLAGE | I10: Oui | J10: Non | K10: =IF(I10<>"Oui","",IF(E10="","",IF(E10<5,"U5",IF(E10<7,"U7",IF(E10<9,"U9",IF(E10<10,"U11",IF(F10="F",IF(E10<12,"U12F","U15F"),IF(E10<11,"U11",IF(E10<13,"U13","U15"))))))))) -> U9 | L10: 1000 | N10: =IF(AND(I10="Oui",J10="Oui"),(L10+M10)*(1-Paramètres!$D$20),L10+M10) -> 1000 | O10: Partiel | P10: 46119 | Q10: manque tt payé bankily | S10: =IF(OR(B10="",R10="",O10="Payé"),"",MAX(0,TODAY()-R10)) | T10: =IF(B10="","",IF(O10="Payé","✅ À jour",IF(R10="","⏳ Pas de date",IF(TODAY()>R10,"🔴 En retard",IF(R10-TODAY()<=7,"🟡 Bientôt dû","🟢 Dans les temps"))))) -> ⏳ Pas de date
A11: 9 | B11: DIARRA | C11: Ibrahim | D11: 40762 | E11: =IF(D11="","",DATEDIF(D11,TODAY(),"Y")) -> 14 | F11: M | G11: +222 41 46 24 13 | H11: 6eme EL MINA | I11: Oui | J11: Non | K11: =IF(I11<>"Oui","",IF(E11="","",IF(E11<5,"U5",IF(E11<7,"U7",IF(E11<9,"U9",IF(E11<10,"U11",IF(F11="F",IF(E11<12,"U12F","U15F"),IF(E11<11,"U11",IF(E11<13,"U13","U15"))))))))) -> U15 | L11: 1000 | N11: =IF(AND(I11="Oui",J11="Oui"),(L11+M11)*(1-Paramètres!$D$20),L11+M11) -> 1000 | O11: Partiel | P11: 46122 | Q11: complét payé bankily | S11: =IF(OR(B11="",R11="",O11="Payé"),"",MAX(0,TODAY()-R11)) | T11: =IF(B11="","",IF(O11="Payé","✅ À jour",IF(R11="","⏳ Pas de date",IF(TODAY()>R11,"🔴 En retard",IF(R11-TODAY()<=7,"🟡 Bientôt dû","🟢 Dans les temps"))))) -> ⏳ Pas de date
A12: 10 | B12: BA | C12: Amadou | D12: 41038 | E12: =IF(D12="","",DATEDIF(D12,TODAY(),"Y")) -> 13 | F12: M | G12: +222 46 33 74 63 | H12: SAMIA EL MINA | I12: Oui | J12: Non | K12: =IF(I12<>"Oui","",IF(E12="","",IF(E12<5,"U5",IF(E12<7,"U7",IF(E12<9,"U9",IF(E12<10,"U11",IF(F12="F",IF(E12<12,"U12F","U15F"),IF(E12<11,"U11",IF(E12<13,"U13","U15"))))))))) -> U15 | L12: 1000 | N12: =IF(AND(I12="Oui",J12="Oui"),(L12+M12)*(1-Paramètres!$D$20),L12+M12) -> 1000 | O12: Partiel | P12: 46120 | Q12: bankily manque identité | S12: =IF(OR(B12="",R12="",O12="Payé"),"",MAX(0,TODAY()-R12)) | T12: =IF(B12="","",IF(O12="Payé","✅ À jour",IF(R12="","⏳ Pas de date",IF(TODAY()>R12,"🔴 En retard",IF(R12-TODAY()<=7,"🟡 Bientôt dû","🟢 Dans les temps"))))) -> ⏳ Pas de date
A13: 11 | B13: SAKHO | C13: Boubou | D13: 40774 | E13: =IF(D13="","",DATEDIF(D13,TODAY(),"Y")) -> 14 | F13: M | G13: +222 49 07 16 53 | H13: CITÉ PLAGE | I13: Oui | J13: Non | K13: =IF(I13<>"Oui","",IF(E13="","",IF(E13<5,"U5",IF(E13<7,"U7",IF(E13<9,"U9",IF(E13<10,"U11",IF(F13="F",IF(E13<12,"U12F","U15F"),IF(E13<11,"U11",IF(E13<13,"U13","U15"))))))))) -> U15 | L13: 2000 | N13: =IF(AND(I13="Oui",J13="Oui"),(L13+M13)*(1-Paramètres!$D$20),L13+M13) -> 2000 | O13: Payé | P13: 46122 | Q13: cash pas de photo payé complementaire le 15/04 | S13: =IF(OR(B13="",R13="",O13="Payé"),"",MAX(0,TODAY()-R13)) | T13: =IF(B13="","",IF(O13="Payé","✅ À jour",IF(R13="","⏳ Pas de date",IF(TODAY()>R13,"🔴 En retard",IF(R13-TODAY()<=7,"🟡 Bientôt dû","🟢 Dans les temps"))))) -> ✅ À jour
A14: 12 | B14: DJIGO | C14: Cheikh bay | D14: 42340 | E14: =IF(D14="","",DATEDIF(D14,TODAY(),"Y")) -> 10 | F14: M | G14: +222 49 47 01 42 | H14: CITÉ PLAGE | I14: Oui | J14: Non | K14: U11 | O14: En attente | S14: " | T14: =IF(B14="","",IF(O14="Payé","✅ À jour",IF(R14="","⏳ Pas de date",IF(TODAY()>R14,"🔴 En retard",IF(R14-TODAY()<=7,"🟡 Bientôt dû","🟢 Dans les temps"))))) -> ⏳ Pas de date
A15: 13 | E15: =IF(D15="","",DATEDIF(D15,TODAY(),"Y")) | K15: =IF(I15<>"Oui","",IF(E15="","",IF(E15<5,"U5",IF(E15<7,"U7",IF(E15<9,"U9",IF(E15<10,"U11",IF(F15="F",IF(E15<12,"U12F","U15F"),IF(E15<11,"U11",IF(E15<13,"U13","U15"))))))))) | T15: =IF(B15="","",IF(O15="Payé","✅ À jour",IF(R15="","⏳ Pas de date",IF(TODAY()>R15,"🔴 En retard",IF(R15-TODAY()<=7,"🟡 Bientôt dû","🟢 Dans les temps")))))
A16: 14 | E16: =IF(D16="","",DATEDIF(D16,TODAY(),"Y")) | K16: =IF(I16<>"Oui","",IF(E16="","",IF(E16<5,"U5",IF(E16<7,"U7",IF(E16<9,"U9",IF(E16<10,"U11",IF(F16="F",IF(E16<12,"U12F","U15F"),IF(E16<11,"U11",IF(E16<13,"U13","U15"))))))))) | S16: =IF(OR(B16="",R16="",O16="Payé"),"",MAX(0,TODAY()-R16)) | T16: =IF(B16="","",IF(O16="Payé","✅ À jour",IF(R16="","⏳ Pas de date",IF(TODAY()>R16,"🔴 En retard",IF(R16-TODAY()<=7,"🟡 Bientôt dû","🟢 Dans les temps")))))
A17: 15 | B17: NBODJ | C17: Babacar | D17: 42736 | E17: =IF(D17="","",DATEDIF(D17,TODAY(),"Y")) -> 9 | F17: M | G17: +222 44 89 97 98 | H17: CITÉ PLAGE | I17: Oui | J17: Non | K17: =IF(I17<>"Oui","",IF(E17="","",IF(E17<5,"U5",IF(E17<7,"U7",IF(E17<9,"U9",IF(E17<10,"U11",IF(F17="F",IF(E17<12,"U12F","U15F"),IF(E17<11,"U11",IF(E17<13,"U13","U15"))))))))) -> U11 | L17: 2000 | N17: =IF(AND(I17="Oui",J17="Oui"),(L17+M17)*(1-Paramètres!$D$20),L17+M17) -> 2000 | O17: Payé | P17: 46120 | Q17: manque extrait complement payment le 24/04 | S17: =IF(OR(B17="",R17="",O17="Payé"),"",MAX(0,TODAY()-R17)) | T17: =IF(B17="","",IF(O17="Payé","✅ À jour",IF(R17="","⏳ Pas de date",IF(TODAY()>R17,"🔴 En retard",IF(R17-TODAY()<=7,"🟡 Bientôt dû","🟢 Dans les temps"))))) -> ✅ À jour
A18: 16 | B18: KANE | C18: Alassane | D18: 44064 | E18: =IF(D18="","",DATEDIF(D18,TODAY(),"Y")) -> 5 | F18: M | G18: +222 42 63 50 50 | H18: EL MINA | I18: Oui | J18: Non | K18: =IF(I18<>"Oui","",IF(E18="","",IF(E18<5,"U5",IF(E18<7,"U7",IF(E18<9,"U9",IF(E18<10,"U11",IF(F18="F",IF(E18<12,"U12F","U15F"),IF(E18<11,"U11",IF(E18<13,"U13","U15"))))))))) -> U7 | L18: 3000 | N18: =IF(AND(I18="Oui",J18="Oui"),(L18+M18)*(1-Paramètres!$D$20),L18+M18) -> 3000 | O18: Payé | P18: 46120 | Q18: manque extrai rajout payment mois le 17/04 | S18: =IF(OR(B18="",R18="",O18="Payé"),"",MAX(0,TODAY()-R18)) | T18: =IF(B18="","",IF(O18="Payé","✅ À jour",IF(R18="","⏳ Pas de date",IF(TODAY()>R18,"🔴 En retard",IF(R18-TODAY()<=7,"🟡 Bientôt dû","🟢 Dans les temps"))))) -> ✅ À jour | V18: il a payé le mois de mai 1000mru 29/04
A19: 17 | B19: DIALLO | C19: Abou | D19: 41134 | E19: =IF(D19="","",DATEDIF(D19,TODAY(),"Y")) -> 13 | F19: M | G19: +222 48 44 07 94 | H19: ILOT L | I19: Oui | J19: Non | K19: =IF(I19<>"Oui","",IF(E19="","",IF(E19<5,"U5",IF(E19<7,"U7",IF(E19<9,"U9",IF(E19<10,"U11",IF(F19="F",IF(E19<12,"U12F","U15F"),IF(E19<11,"U11",IF(E19<13,"U13","U15"))))))))) -> U15 | L19: 2000 | N19: =IF(AND(I19="Oui",J19="Oui"),(L19+M19)*(1-Paramètres!$D$20),L19+M19) -> 2000 | O19: Payé | P19: 46122 | Q19: manque extrait bankily | S19: =IF(OR(B19="",R19="",O19="Payé"),"",MAX(0,TODAY()-R19)) | T19: =IF(B19="","",IF(O19="Payé","✅ À jour",IF(R19="","⏳ Pas de date",IF(TODAY()>R19,"🔴 En retard",IF(R19-TODAY()<=7,"🟡 Bientôt dû","🟢 Dans les temps"))))) -> ✅ À jour
A20: 18 | B20: SOW | C20: Mohamed | D20: 42598 | E20: =IF(D20="","",DATEDIF(D20,TODAY(),"Y")) -> 9 | F20: M | G20: +222 44 89 97 98 | H20: CITÉ PLAGE | I20: Oui | K20: =IF(I20<>"Oui","",IF(E20="","",IF(E20<5,"U5",IF(E20<7,"U7",IF(E20<9,"U9",IF(E20<10,"U11",IF(F20="F",IF(E20<12,"U12F","U15F"),IF(E20<11,"U11",IF(E20<13,"U13","U15"))))))))) -> U11 | Q20: document ok payement ? | S20: =IF(OR(B20="",R20="",O20="Payé"),"",MAX(0,TODAY()-R20)) | T20: =IF(B20="","",IF(O20="Payé","✅ À jour",IF(R20="","⏳ Pas de date",IF(TODAY()>R20,"🔴 En retard",IF(R20-TODAY()<=7,"🟡 Bientôt dû","🟢 Dans les temps"))))) -> ⏳ Pas de date
A21: 19 | B21: DIALLO | C21: Souleymane | D21: 42896 | E21: =IF(D21="","",DATEDIF(D21,TODAY(),"Y")) -> 8 | F21: M | G21: +222 26 31 86 93 | H21: CITÉ PLAGE | I21: Oui | K21: =IF(I21<>"Oui","",IF(E21="","",IF(E21<5,"U5",IF(E21<7,"U7",IF(E21<9,"U9",IF(E21<10,"U11",IF(F21="F",IF(E21<12,"U12F","U15F"),IF(E21<11,"U11",IF(E21<13,"U13","U15"))))))))) -> U9 | O21: Partiel | Q21: pas de doc payement ? | S21: =IF(OR(B21="",R21="",O21="Payé"),"",MAX(0,TODAY()-R21)) | T21: =IF(B21="","",IF(O21="Payé","✅ À jour",IF(R21="","⏳ Pas de date",IF(TODAY()>R21,"🔴 En retard",IF(R21-TODAY()<=7,"🟡 Bientôt dû","🟢 Dans les temps"))))) -> ⏳ Pas de date
A22: 20 | E22: =IF(D22="","",DATEDIF(D22,TODAY(),"Y")) | K22: =IF(I22<>"Oui","",IF(E22="","",IF(E22<5,"U5",IF(E22<7,"U7",IF(E22<9,"U9",IF(E22<10,"U11",IF(F22="F",IF(E22<12,"U12F","U15F"),IF(E22<11,"U11",IF(E22<13,"U13","U15"))))))))) | S22: =IF(OR(B22="",R22="",O22="Payé"),"",MAX(0,TODAY()-R22)) | T22: =IF(B22="","",IF(O22="Payé","✅ À jour",IF(R22="","⏳ Pas de date",IF(TODAY()>R22,"🔴 En retard",IF(R22-TODAY()<=7,"🟡 Bientôt dû","🟢 Dans les temps")))))
A23: 21 | E23: =IF(D23="","",DATEDIF(D23,TODAY(),"Y")) | K23: =IF(I23<>"Oui","",IF(E23="","",IF(E23<5,"U5",IF(E23<7,"U7",IF(E23<9,"U9",IF(E23<10,"U11",IF(F23="F",IF(E23<12,"U12F","U15F"),IF(E23<11,"U11",IF(E23<13,"U13","U15"))))))))) | N23: =IF(AND(I23="Oui",J23="Oui"),(L23+M23)*(1-Paramètres!$D$20),L23+M23) -> 0 | S23: =IF(OR(B23="",R23="",O23="Payé"),"",MAX(0,TODAY()-R23)) | T23: =IF(B23="","",IF(O23="Payé","✅ À jour",IF(R23="","⏳ Pas de date",IF(TODAY()>R23,"🔴 En retard",IF(R23-TODAY()<=7,"🟡 Bientôt dû","🟢 Dans les temps")))))
A24: 22 | B24: KERKOUB | C24: Nenime | D24: 41569 | E24: =IF(D24="","",DATEDIF(D24,TODAY(),"Y")) -> 12 | F24: M | G24: +222 47 45 20 20 | H24: TERVRAGH ZEINA | I24: Oui | K24: =IF(I24<>"Oui","",IF(E24="","",IF(E24<5,"U5",IF(E24<7,"U7",IF(E24<9,"U9",IF(E24<10,"U11",IF(F24="F",IF(E24<12,"U12F","U15F"),IF(E24<11,"U11",IF(E24<13,"U13","U15"))))))))) -> U13 | L24: 2000 | N24: =IF(AND(I24="Oui",J24="Oui"),(L24+M24)*(1-Paramètres!$D$20),L24+M24) -> 2000 | O24: Payé | P24: 46117 | Q24: CASH COMPLET | S24: =IF(OR(B24="",R24="",O24="Payé"),"",MAX(0,TODAY()-R24)) | T24: =IF(B24="","",IF(O24="Payé","✅ À jour",IF(R24="","⏳ Pas de date",IF(TODAY()>R24,"🔴 En retard",IF(R24-TODAY()<=7,"🟡 Bientôt dû","🟢 Dans les temps"))))) -> ✅ À jour
A25: 23 | B25: DIAGANA | C25: Bocar | D25: 43252 | E25: =IF(D25="","",DATEDIF(D25,TODAY(),"Y")) -> 7 | F25: M | G25: +222 47 47 77 77 | H25: CITÉ PLAGE | I25: Oui | K25: =IF(I25<>"Oui","",IF(E25="","",IF(E25<5,"U5",IF(E25<7,"U7",IF(E25<9,"U9",IF(E25<10,"U11",IF(F25="F",IF(E25<12,"U12F","U15F"),IF(E25<11,"U11",IF(E25<13,"U13","U15"))))))))) -> U9 | L25: 2000 | N25: =IF(AND(I25="Oui",J25="Oui"),(L25+M25)*(1-Paramètres!$D$20),L25+M25) -> 2000 | O25: Payé | P25: 46117 | Q25: MANQUE PIECS | S25: =IF(OR(B25="",R25="",O25="Payé"),"",MAX(0,TODAY()-R25)) | T25: =IF(B25="","",IF(O25="Payé","✅ À jour",IF(R25="","⏳ Pas de date",IF(TODAY()>R25,"🔴 En retard",IF(R25-TODAY()<=7,"🟡 Bientôt dû","🟢 Dans les temps"))))) -> ✅ À jour
A26: 24 | B26: BA | C26: Mohamed | D26: 44503 | E26: =IF(D26="","",DATEDIF(D26,TODAY(),"Y")) -> 4 | F26: M | G26: +222 47 75 77 22 | H26: CITÉ PLAGE | I26: Oui | K26: =IF(I26<>"Oui","",IF(E26="","",IF(E26<5,"U5",IF(E26<7,"U7",IF(E26<9,"U9",IF(E26<10,"U11",IF(F26="F",IF(E26<12,"U12F","U15F"),IF(E26<11,"U11",IF(E26<13,"U13","U15"))))))))) -> U5 | L26: 2000 | N26: =IF(AND(I26="Oui",J26="Oui"),(L26+M26)*(1-Paramètres!$D$20),L26+M26) -> 2000 | O26: Payé | P26: 46117 | Q26: dit quil a laissé | S26: =IF(OR(B26="",R26="",O26="Payé"),"",MAX(0,TODAY()-R26)) | T26: =IF(B26="","",IF(O26="Payé","✅ À jour",IF(R26="","⏳ Pas de date",IF(TODAY()>R26,"🔴 En retard",IF(R26-TODAY()<=7,"🟡 Bientôt dû","🟢 Dans les temps"))))) -> ✅ À jour
A27: 25 | B27: BA | C27: Amadou | D27: 42852 | E27: =IF(D27="","",DATEDIF(D27,TODAY(),"Y")) -> 9 | F27: M | G27: +222 47 75 77 22 | H27: CITÉ PLAGE | I27: Oui | K27: =IF(I27<>"Oui","",IF(E27="","",IF(E27<5,"U5",IF(E27<7,"U7",IF(E27<9,"U9",IF(E27<10,"U11",IF(F27="F",IF(E27<12,"U12F","U15F"),IF(E27<11,"U11",IF(E27<13,"U13","U15"))))))))) -> U11 | L27: 2000 | N27: =IF(AND(I27="Oui",J27="Oui"),(L27+M27)*(1-Paramètres!$D$20),L27+M27) -> 2000 | O27: Payé | P27: 46117 | Q27: dit quil a laissé payé le 29/04 masravi mensualité | S27: =IF(OR(B27="",R27="",O27="Payé"),"",MAX(0,TODAY()-R27)) | T27: =IF(B27="","",IF(O27="Payé","✅ À jour",IF(R27="","⏳ Pas de date",IF(TODAY()>R27,"🔴 En retard",IF(R27-TODAY()<=7,"🟡 Bientôt dû","🟢 Dans les temps"))))) -> ✅ À jour
A28: 26 | B28: SIDI MAOULOUD | C28: Abdallahi | D28: 43957 | E28: =IF(D28="","",DATEDIF(D28,TODAY(),"Y")) -> 5 | F28: M | G28: +222 36 29 01 29 | H28: CITÉ PLAGE | I28: Oui | K28: =IF(I28<>"Oui","",IF(E28="","",IF(E28<5,"U5",IF(E28<7,"U7",IF(E28<9,"U9",IF(E28<10,"U11",IF(F28="F",IF(E28<12,"U12F","U15F"),IF(E28<11,"U11",IF(E28<13,"U13","U15"))))))))) -> U7 | L28: 2000 | N28: =IF(AND(I28="Oui",J28="Oui"),(L28+M28)*(1-Paramètres!$D$20),L28+M28) -> 2000 | O28: Payé | P28: 46117 | Q28: bankily piece ? | S28: =IF(OR(B28="",R28="",O28="Payé"),"",MAX(0,TODAY()-R28)) | T28: =IF(B28="","",IF(O28="Payé","✅ À jour",IF(R28="","⏳ Pas de date",IF(TODAY()>R28,"🔴 En retard",IF(R28-TODAY()<=7,"🟡 Bientôt dû","🟢 Dans les temps"))))) -> ✅ À jour
A29: 27 | B29: SY | C29: Boubacar | D29: 43115 | E29: =IF(D29="","",DATEDIF(D29,TODAY(),"Y")) -> 8 | F29: M | G29: +222 44 24 22 34 | H29: BASRA | I29: Oui | K29: =IF(I29<>"Oui","",IF(E29="","",IF(E29<5,"U5",IF(E29<7,"U7",IF(E29<9,"U9",IF(E29<10,"U11",IF(F29="F",IF(E29<12,"U12F","U15F"),IF(E29<11,"U11",IF(E29<13,"U13","U15"))))))))) -> U9 | L29: 1000 | N29: =IF(AND(I29="Oui",J29="Oui"),(L29+M29)*(1-Paramètres!$D$20),L29+M29) -> 1000 | O29: Partiel | P29: 46117 | Q29: payé masravi manque photot | S29: =IF(OR(B29="",R29="",O29="Payé"),"",MAX(0,TODAY()-R29)) | T29: =IF(B29="","",IF(O29="Payé","✅ À jour",IF(R29="","⏳ Pas de date",IF(TODAY()>R29,"🔴 En retard",IF(R29-TODAY()<=7,"🟡 Bientôt dû","🟢 Dans les temps"))))) -> ⏳ Pas de date
A30: 28 | B30: KANOUTÉ | C30: Mohamed | D30: 43612 | E30: =IF(D30="","",DATEDIF(D30,TODAY(),"Y")) -> 6 | F30: M | G30: 212658200457 | H30: CITÉ PLAGE | I30: Oui | K30: =IF(I30<>"Oui","",IF(E30="","",IF(E30<5,"U5",IF(E30<7,"U7",IF(E30<9,"U9",IF(E30<10,"U11",IF(F30="F",IF(E30<12,"U12F","U15F"),IF(E30<11,"U11",IF(E30<13,"U13","U15"))))))))) -> U7 | L30: 1000 | N30: =IF(AND(I30="Oui",J30="Oui"),(L30+M30)*(1-Paramètres!$D$20),L30+M30) -> 1000 | O30: Payé | P30: 46117 | Q30: manque extrait payé bankly payé le 15 | S30: =IF(OR(B30="",R30="",O30="Payé"),"",MAX(0,TODAY()-R30)) | T30: =IF(B30="","",IF(O30="Payé","✅ À jour",IF(R30="","⏳ Pas de date",IF(TODAY()>R30,"🔴 En retard",IF(R30-TODAY()<=7,"🟡 Bientôt dû","🟢 Dans les temps"))))) -> ✅ À jour
A31: 29 | B31: GUEYE | C31: Moussa | D31: 43110 | E31: =IF(D31="","",DATEDIF(D31,TODAY(),"Y")) -> 8 | F31: M | G31: +222 47 32 19 97 | H31: KOUFA | I31: Oui | K31: =IF(I31<>"Oui","",IF(E31="","",IF(E31<5,"U5",IF(E31<7,"U7",IF(E31<9,"U9",IF(E31<10,"U11",IF(F31="F",IF(E31<12,"U12F","U15F"),IF(E31<11,"U11",IF(E31<13,"U13","U15"))))))))) -> U9 | L31: 2000 | N31: =IF(AND(I31="Oui",J31="Oui"),(L31+M31)*(1-Paramètres!$D$20),L31+M31) -> 2000 | O31: Partiel | P31: 46117 | Q31: complet | S31: =IF(OR(B31="",R31="",O31="Payé"),"",MAX(0,TODAY()-R31)) | T31: =IF(B31="","",IF(O31="Payé","✅ À jour",IF(R31="","⏳ Pas de date",IF(TODAY()>R31,"🔴 En retard",IF(R31-TODAY()<=7,"🟡 Bientôt dû","🟢 Dans les temps"))))) -> ⏳ Pas de date
A32: 30 | B32: GUEYE | C32: Mademba | D32: 42624 | E32: =IF(D32="","",DATEDIF(D32,TODAY(),"Y")) -> 9 | F32: M | G32: +222 47 32 19 97 | H32: KOUFA | I32: Oui | K32: =IF(I32<>"Oui","",IF(E32="","",IF(E32<5,"U5",IF(E32<7,"U7",IF(E32<9,"U9",IF(E32<10,"U11",IF(F32="F",IF(E32<12,"U12F","U15F"),IF(E32<11,"U11",IF(E32<13,"U13","U15"))))))))) -> U11 | L32: 1000 | N32: =IF(AND(I32="Oui",J32="Oui"),(L32+M32)*(1-Paramètres!$D$20),L32+M32) -> 1000 | O32: Partiel | P32: 46117 | S32: =IF(OR(B32="",R32="",O32="Payé"),"",MAX(0,TODAY()-R32)) | T32: =IF(B32="","",IF(O32="Payé","✅ À jour",IF(R32="","⏳ Pas de date",IF(TODAY()>R32,"🔴 En retard",IF(R32-TODAY()<=7,"🟡 Bientôt dû","🟢 Dans les temps"))))) -> ⏳ Pas de date
A33: 31 | B33: THIAM | C33: Adama | D33: 43781 | E33: =IF(D33="","",DATEDIF(D33,TODAY(),"Y")) -> 6 | F33: M | G33: +222 44 89 92 74 | H33: PK9 | I33: Oui | K33: =IF(I33<>"Oui","",IF(E33="","",IF(E33<5,"U5",IF(E33<7,"U7",IF(E33<9,"U9",IF(E33<10,"U11",IF(F33="F",IF(E33<12,"U12F","U15F"),IF(E33<11,"U11",IF(E33<13,"U13","U15"))))))))) -> U7 | L33: 2000 | N33: =IF(AND(I33="Oui",J33="Oui"),(L33+M33)*(1-Paramètres!$D$20),L33+M33) -> 2000 | O33: Payé | P33: 46117 | Q33: dossier complet fait le completment le 24/04 | S33: =IF(OR(B33="",R33="",O33="Payé"),"",MAX(0,TODAY()-R33)) | T33: =IF(B33="","",IF(O33="Payé","✅ À jour",IF(R33="","⏳ Pas de date",IF(TODAY()>R33,"🔴 En retard",IF(R33-TODAY()<=7,"🟡 Bientôt dû","🟢 Dans les temps"))))) -> ✅ À jour
A34: 32 | B34: TOURÉ | C34: Mohamed | D34: 44130 | E34: =IF(D34="","",DATEDIF(D34,TODAY(),"Y")) -> 5 | F34: M | G34: +222 46 85 01 86 | H34: SOCOGIM | I34: Oui | K34: =IF(I34<>"Oui","",IF(E34="","",IF(E34<5,"U5",IF(E34<7,"U7",IF(E34<9,"U9",IF(E34<10,"U11",IF(F34="F",IF(E34<12,"U12F","U15F"),IF(E34<11,"U11",IF(E34<13,"U13","U15"))))))))) -> U7 | L34: 1000 | N34: =IF(AND(I34="Oui",J34="Oui"),(L34+M34)*(1-Paramètres!$D$20),L34+M34) -> 1000 | O34: Partiel | P34: 46117 | Q34: complet | S34: =IF(OR(B34="",R34="",O34="Payé"),"",MAX(0,TODAY()-R34)) | T34: =IF(B34="","",IF(O34="Payé","✅ À jour",IF(R34="","⏳ Pas de date",IF(TODAY()>R34,"🔴 En retard",IF(R34-TODAY()<=7,"🟡 Bientôt dû","🟢 Dans les temps"))))) -> ⏳ Pas de date
A35: 33 | B35: TOURÉ | C35: Ciré | D35: 43034 | E35: =IF(D35="","",DATEDIF(D35,TODAY(),"Y")) -> 8 | F35: M | G35: +222 46 85 01 86 | H35: SOCOGIM | I35: Oui | K35: =IF(I35<>"Oui","",IF(E35="","",IF(E35<5,"U5",IF(E35<7,"U7",IF(E35<9,"U9",IF(E35<10,"U11",IF(F35="F",IF(E35<12,"U12F","U15F"),IF(E35<11,"U11",IF(E35<13,"U13","U15"))))))))) -> U9 | L35: 1000 | N35: =IF(AND(I35="Oui",J35="Oui"),(L35+M35)*(1-Paramètres!$D$20),L35+M35) -> 1000 | O35: Partiel | P35: 46117 | Q35: complet | S35: =IF(OR(B35="",R35="",O35="Payé"),"",MAX(0,TODAY()-R35)) | T35: =IF(B35="","",IF(O35="Payé","✅ À jour",IF(R35="","⏳ Pas de date",IF(TODAY()>R35,"🔴 En retard",IF(R35-TODAY()<=7,"🟡 Bientôt dû","🟢 Dans les temps"))))) -> ⏳ Pas de date
A36: 34 | B36: SIDIBÉ | C36: Amatullah | D36: 41972 | E36: =IF(D36="","",DATEDIF(D36,TODAY(),"Y")) -> 11 | F36: F | G36: ‪+33 6 58 40 25 02‬ | H36: BASRA | I36: Oui | K36: =IF(I36<>"Oui","",IF(E36="","",IF(E36<5,"U5",IF(E36<7,"U7",IF(E36<9,"U9",IF(E36<10,"U11",IF(F36="F",IF(E36<12,"U12F","U15F"),IF(E36<11,"U11",IF(E36<13,"U13","U15"))))))))) -> U12F | L36: 1750 | N36: =IF(AND(I36="Oui",J36="Oui"),(L36+M36)*(1-Paramètres!$D$20),L36+M36) -> 1750 | O36: Payé | P36: 46122 | S36: =IF(OR(B36="",R36="",O36="Payé"),"",MAX(0,TODAY()-R36)) | T36: =IF(B36="","",IF(O36="Payé","✅ À jour",IF(R36="","⏳ Pas de date",IF(TODAY()>R36,"🔴 En retard",IF(R36-TODAY()<=7,"🟡 Bientôt dû","🟢 Dans les temps"))))) -> ✅ À jour
A37: 35 | B37: SIDIBÉ | C37: Soukaïna | D37: 44316 | E37: =IF(D37="","",DATEDIF(D37,TODAY(),"Y")) -> 5 | F37: F | G37: ‪+33 6 58 40 25 02‬ | H37: BASRA | I37: Oui | K37: =IF(I37<>"Oui","",IF(E37="","",IF(E37<5,"U5",IF(E37<7,"U7",IF(E37<9,"U9",IF(E37<10,"U11",IF(F37="F",IF(E37<12,"U12F","U15F"),IF(E37<11,"U11",IF(E37<13,"U13","U15"))))))))) -> U7 | L37: 500 | N37: =IF(AND(I37="Oui",J37="Oui"),(L37+M37)*(1-Paramètres!$D$20),L37+M37) -> 500 | O37: Payé | P37: 46122 | S37: =IF(OR(B37="",R37="",O37="Payé"),"",MAX(0,TODAY()-R37)) | T37: =IF(B37="","",IF(O37="Payé","✅ À jour",IF(R37="","⏳ Pas de date",IF(TODAY()>R37,"🔴 En retard",IF(R37-TODAY()<=7,"🟡 Bientôt dû","🟢 Dans les temps"))))) -> ✅ À jour
A38: 36 | B38: BA | C38: Mouhamed | D38: 42347 | E38: =IF(D38="","",DATEDIF(D38,TODAY(),"Y")) -> 10 | F38: M | G38: +222 42 02 35 84 | H38: KOUFA | I38: Oui | K38: =IF(I38<>"Oui","",IF(E38="","",IF(E38<5,"U5",IF(E38<7,"U7",IF(E38<9,"U9",IF(E38<10,"U11",IF(F38="F",IF(E38<12,"U12F","U15F"),IF(E38<11,"U11",IF(E38<13,"U13","U15"))))))))) -> U11 | L38: 2000 | N38: =IF(AND(I38="Oui",J38="Oui"),(L38+M38)*(1-Paramètres!$D$20),L38+M38) -> 2000 | O38: Payé | P38: 46117 | Q38: payé par bankily payé le reste 29/04 | S38: =IF(OR(B38="",R38="",O38="Payé"),"",MAX(0,TODAY()-R38)) | T38: =IF(B38="","",IF(O38="Payé","✅ À jour",IF(R38="","⏳ Pas de date",IF(TODAY()>R38,"🔴 En retard",IF(R38-TODAY()<=7,"🟡 Bientôt dû","🟢 Dans les temps"))))) -> ✅ À jour
A39: 37 | B39: BA | C39: Mamadou | D39: 41618 | E39: =IF(D39="","",DATEDIF(D39,TODAY(),"Y")) -> 12 | F39: M | G39: +222 42 02 35 84 | H39: KOUFA | I39: Oui | K39: =IF(I39<>"Oui","",IF(E39="","",IF(E39<5,"U5",IF(E39<7,"U7",IF(E39<9,"U9",IF(E39<10,"U11",IF(F39="F",IF(E39<12,"U12F","U15F"),IF(E39<11,"U11",IF(E39<13,"U13","U15"))))))))) -> U13 | L39: 2000 | N39: =IF(AND(I39="Oui",J39="Oui"),(L39+M39)*(1-Paramètres!$D$20),L39+M39) -> 2000 | O39: Payé | P39: 46117 | Q39: payé bankily le reste le 29/04 | S39: =IF(OR(B39="",R39="",O39="Payé"),"",MAX(0,TODAY()-R39)) | T39: =IF(B39="","",IF(O39="Payé","✅ À jour",IF(R39="","⏳ Pas de date",IF(TODAY()>R39,"🔴 En retard",IF(R39-TODAY()<=7,"🟡 Bientôt dû","🟢 Dans les temps"))))) -> ✅ À jour
A40: 38 | B40: SAMASSA | C40: Abdrahmane | D40: 42028 | E40: =IF(D40="","",DATEDIF(D40,TODAY(),"Y")) -> 11 | F40: M | G40: +222 26 31 86 93 | H40: TEYARETE | I40: Oui | K40: =IF(I40<>"Oui","",IF(E40="","",IF(E40<5,"U5",IF(E40<7,"U7",IF(E40<9,"U9",IF(E40<10,"U11",IF(F40="F",IF(E40<12,"U12F","U15F"),IF(E40<11,"U11",IF(E40<13,"U13","U15"))))))))) -> U13 | L40: 2000 | N40: =IF(AND(I40="Oui",J40="Oui"),(L40+M40)*(1-Paramètres!$D$20),L40+M40) -> 2000 | O40: Payé | P40: 46122 | Q40: complet payé 17 | S40: =IF(OR(B40="",R40="",O40="Payé"),"",MAX(0,TODAY()-R40)) | T40: =IF(B40="","",IF(O40="Payé","✅ À jour",IF(R40="","⏳ Pas de date",IF(TODAY()>R40,"🔴 En retard",IF(R40-TODAY()<=7,"🟡 Bientôt dû","🟢 Dans les temps"))))) -> ✅ À jour
...

Sheet Tableau de Bord
A1: 📊 FIVEUR ACADEMY — TABLEAU DE BORD
A2: INDICATEURS CLÉS
A3: Total Inscrits | D3: =COUNTA(Inscriptions!B3:B202) -> 117
A4: Inscrits Football | D4: =COUNTIF(Inscriptions!I3:I202,"Oui") -> 116
A5: Inscrits Loisirs | D5: =COUNTIF(Inscriptions!J3:J202,"Oui") -> 0
A6: Inscrits Football + Loisirs | D6: =COUNTIFS(Inscriptions!I3:I202,"Oui",Inscriptions!J3:J202,"Oui") -> 0
A7: Garçons | D7: =COUNTIF(Inscriptions!F3:F202,"M") -> 106
A8: Filles | D8: =COUNTIF(Inscriptions!F3:F202,"F") -> 11
A11: RÉPARTITION PAR CATÉGORIE (Football)
A12: Catégorie | B12: Nb Inscrits | C12: Garçons | D12: Filles | E12: % du Total | F12: CA Mensuel
A13: U5 | B13: =COUNTIF(Inscriptions!K3:K202,A13) -> 6 | C13: =COUNTIFS(Inscriptions!K3:K202,A13,Inscriptions!F3:F202,"M") -> 6 | D13: =COUNTIFS(Inscriptions!K3:K202,A13,Inscriptions!F3:F202,"F") -> 0 | E13: =IF(D$3=0,0,B13/D$3) -> 0.051282051 | F13: =B13*VLOOKUP(A13,Paramètres!$A$6:$D$13,4,FALSE()) -> 15000
A14: U7 | B14: =COUNTIF(Inscriptions!K3:K202,A14) -> 17 | C14: =COUNTIFS(Inscriptions!K3:K202,A14,Inscriptions!F3:F202,"M") -> 16 | D14: =COUNTIFS(Inscriptions!K3:K202,A14,Inscriptions!F3:F202,"F") -> 1 | E14: =IF(D$3=0,0,B14/D$3) -> 0.14529915 | F14: =B14*VLOOKUP(A14,Paramètres!$A$6:$D$13,4,FALSE()) -> 51000
A15: U9 | B15: =COUNTIF(Inscriptions!K3:K202,A15) -> 18 | C15: =COUNTIFS(Inscriptions!K3:K202,A15,Inscriptions!F3:F202,"M") -> 16 | D15: =COUNTIFS(Inscriptions!K3:K202,A15,Inscriptions!F3:F202,"F") -> 2 | E15: =IF(D$3=0,0,B15/D$3) -> 0.15384615 | F15: =B15*VLOOKUP(A15,Paramètres!$A$6:$D$13,4,FALSE()) -> 63000
A16: U11 | B16: =COUNTIF(Inscriptions!K3:K202,A16) -> 26 | C16: =COUNTIFS(Inscriptions!K3:K202,A16,Inscriptions!F3:F202,"M") -> 25 | D16: =COUNTIFS(Inscriptions!K3:K202,A16,Inscriptions!F3:F202,"F") -> 1 | E16: =IF(D$3=0,0,B16/D$3) -> 0.22222222 | F16: =B16*VLOOKUP(A16,Paramètres!$A$6:$D$13,4,FALSE()) -> 104000
A17: U12F | B17: =COUNTIF(Inscriptions!K3:K202,A17) -> 4 | C17: =COUNTIFS(Inscriptions!K3:K202,A17,Inscriptions!F3:F202,"M") -> 0 | D17: =COUNTIFS(Inscriptions!K3:K202,A17,Inscriptions!F3:F202,"F") -> 4 | E17: =IF(D$3=0,0,B17/D$3) -> 0.034188034 | F17: =B17*VLOOKUP(A17,Paramètres!$A$6:$D$13,4,FALSE()) -> 16000
A18: U13 | B18: =COUNTIF(Inscriptions!K3:K202,A18) -> 16 | C18: =COUNTIFS(Inscriptions!K3:K202,A18,Inscriptions!F3:F202,"M") -> 16 | D18: =COUNTIFS(Inscriptions!K3:K202,A18,Inscriptions!F3:F202,"F") -> 0 | E18: =IF(D$3=0,0,B18/D$3) -> 0.13675214 | F18: =B18*VLOOKUP(A18,Paramètres!$A$6:$D$13,4,FALSE()) -> 72000
A19: U15 | B19: =COUNTIF(Inscriptions!K3:K202,A19) -> 23 | C19: =COUNTIFS(Inscriptions!K3:K202,A19,Inscriptions!F3:F202,"M") -> 23 | D19: =COUNTIFS(Inscriptions!K3:K202,A19,Inscriptions!F3:F202,"F") -> 0 | E19: =IF(D$3=0,0,B19/D$3) -> 0.1965812 | F19: =B19*VLOOKUP(A19,Paramètres!$A$6:$D$13,4,FALSE()) -> 115000
A20: U15F | B20: =COUNTIF(Inscriptions!K3:K202,A20) -> 2 | C20: =COUNTIFS(Inscriptions!K3:K202,A20,Inscriptions!F3:F202,"M") -> 0 | D20: =COUNTIFS(Inscriptions!K3:K202,A20,Inscriptions!F3:F202,"F") -> 2 | E20: =IF(D$3=0,0,B20/D$3) -> 0.017094017 | F20: =B20*VLOOKUP(A20,Paramètres!$A$6:$D$13,4,FALSE()) -> 10000
A21: TOTAL | B21: =SUM(B13:B20) -> 112 | C21: =SUM(C13:C20) -> 102 | D21: =SUM(D13:D20) -> 10 | E21: =IF(SUM(B13:B20)=0,0,1) -> 1 | F21: =SUM(F13:F20) -> 446000
A24: SYNTHÈSE FINANCIÈRE
A25: CA Football Mensuel | D25: =SUM(Inscriptions!L3:L202) -> 164250
A26: CA Loisirs Mensuel | D26: =SUM(Inscriptions!M3:M202) -> 0
A27: Réductions Combo | D27: =SUM(Inscriptions!L3:L202)+SUM(Inscriptions!M3:M202)-SUM(Inscriptions!N3:N202) -> 35500
A28: CA Total Mensuel (net) | D28: =SUM(Inscriptions!N3:N202) -> 128750
A29: CA Total Annuel (estimé) | D29: =D28*12 -> 1545000
A30: Paiements Reçus (Payé) | D30: =SUMPRODUCT((Inscriptions!O3:O202="Payé")*Inscriptions!N3:N202) -> 91750
A31: Paiements En Attente | D31: =SUMPRODUCT((Inscriptions!O3:O202="En attente")*Inscriptions!N3:N202) -> 0
A32: Taux de Recouvrement | D32: =IF(D28=0,0,D30/D28) -> 0.71262136
A35: SUIVI DES PAIEMENTS
A36: Nb Payé | D36: =COUNTIF(Inscriptions!O3:O202,"Payé") -> 59
A37: Nb En Attente | D37: =COUNTIF(Inscriptions!O3:O202,"En attente") -> 5
A38: Nb Partiel | D38: =COUNTIF(Inscriptions!O3:O202,"Partiel") -> 49
A39: % Payé | D39: =IF(D3=0,0,D36/D3) -> 0.5042735
A42: SUIVI DES RETARDS
A43: 🟢 Dans les temps | D43: =COUNTIF(Inscriptions!T3:T202,"*Dans les temps*") -> 0
A44: 🟡 Bientôt dû (< 7 jours) | D44: =COUNTIF(Inscriptions!T3:T202,"*Bientôt*") -> 0
A45: 🔴 En retard | D45: =COUNTIF(Inscriptions!T3:T202,"*retard*") -> 1
A46: ✅ À jour (payé) | D46: =COUNTIF(Inscriptions!T3:T202,"*jour*") -> 59
A47: Retard moyen (jours) | D47: =IF(COUNTIF(Inscriptions!S3:S202,">"&0)=0,0,AVERAGEIF(Inscriptions!S3:S202,">"&0)) -> 27

Sheet Rappels Paiement
A1: 📱 FIVEUR ACADEMY — RAPPELS DE PAIEMENT
A2: ✏️ MODÈLES DE MESSAGES (personnalisez ci-dessous)
A3: Modèle 1 : | C3: Bonjour, ceci est un rappel de la Fiveur Academy. Le paiement de {MONTANT} pour l'inscription de {PRENOM} {NOM} ({PRESTATION}) est en attente. Date limite : {DATE_LIMITE}. Merci de régulariser. Cordialement, Fiveur Academy.
A4: Modèle 2 : | C4: ⚠️ Bonjour, la Fiveur Academy vous informe que le paiement de {MONTANT} pour {PRENOM} {NOM} est en retard de {RETARD} jour(s). Merci de procéder au règlement dans les plus brefs délais pour maintenir l'inscription. Contact : Fiveur Academy.
A5: Modèle 3 : | C5: ✅ Bonjour, la Fiveur Academy confirme la réception du paiement de {MONTANT} pour {PRENOM} {NOM}. Inscription validée pour : {PRESTATION}. Merci de votre confiance ! ⚽ Fiveur Academy — Since 2023.
A7: 📋 MESSAGES GÉNÉRÉS AUTOMATIQUEMENT (copier-coller vers WhatsApp/SMS)
A8: N° | B8: Nom | C8: Prénom | D8: Téléphone | E8: Prestation | F8: Montant | G8: Statut | H8: Retard | I8: Type Rappel | J8: 📱 Message à Envoyer
A9: =IF(Inscriptions!B3="","",Inscriptions!A3) -> 1 | B9: =IF(Inscriptions!B3="","",Inscriptions!B3) -> SIDIBÉ | C9: =IF(Inscriptions!B3="","",Inscriptions!C3) -> Younous | D9: =IF(Inscriptions!B3="","",Inscriptions!G3) -> +222 49 83 01 84 | E9: =IF(Inscriptions!B3="","",IF(AND(Inscriptions!I3="Oui",Inscriptions!J3="Oui"),"Football + Loisirs",IF(Inscriptions!I3="Oui","Football",IF(Inscriptions!J3="Oui","Centre Loisirs","")))) -> Football | F9: =IF(Inscriptions!B3="","",Inscriptions!N3) -> 1750 | G9: =IF(Inscriptions!B3="","",Inscriptions!O3) -> Payé | H9: =IF(Inscriptions!B3="","",IF(Inscriptions!S3="","—",Inscriptions!S3&" j")) -> — | I9: =IF(Inscriptions!B3="","",IF(Inscriptions!O3="Payé","✅ Confirmation",IF(AND(Inscriptions!S3<>"",Inscriptions!S3>0),"🔴 Retard","🟡 Rappel"))) -> ✅ Confirmation | J9: =IF(Inscriptions!B3="","",IF(Inscriptions!O3="Payé",SUBSTITUTE(SUBSTITUTE(SUBSTITUTE(SUBSTITUTE(C5,"{MONTANT}",TEXT(Inscriptions!N3,"#,##0")&" MRU"),"{PRENOM}",Inscriptions!C3),"{NOM}",Inscriptions!B3),"{PRESTATION}",E9),IF(AND(Inscriptions!S3<>"",Inscriptions!S3>0),SUBSTITUTE(SUBSTITUTE(SUBSTITUTE(SUBSTITUTE(C4,"{MONTANT}",TEXT(Inscriptions!N3,"#,##0")&" MRU"),"{PRENOM}",Inscriptions!C3),"{NOM}",Inscriptions!B3),"{RETARD}",TEXT(Inscriptions!S3,"0")),SUBSTITUTE(SUBSTITUTE(SUBSTITUTE(SUBSTITUTE(SUBSTITUTE(C3,"{MONTANT}",TEXT(Inscriptions!N3,"#,##0")&" MRU"),"{PRENOM}",Inscriptions!C3),"{NOM}",Inscriptions!B3),"{PRESTATION}",E9),"{DATE_LIMITE}",IF(Inscriptions!R3="","non définie",TEXT(Inscriptions!R3,"DD/MM/YYYY")))))) -> ✅ Bonjour, la Fiveur Academy confirme la réception du paiement de 1750,0 MRU pour Younous SIDIBÉ. Inscription validée pour : Football. Merci de votre confiance ! ⚽ Fiveur Academy — Since 2023.
A10: =IF(Inscriptions!B4="","",Inscriptions!A4) -> 2 | B10: =IF(Inscriptions!B4="","",Inscriptions!B4) -> SIDIBÉ | C10: =IF(Inscriptions!B4="","",Inscriptions!C4) -> Zackaria | D10: =IF(Inscriptions!B4="","",Inscriptions!G4) -> +222 49 83 01 84 | E10: =IF(Inscriptions!B4="","",IF(AND(Inscriptions!I4="Oui",Inscriptions!J4="Oui"),"Football + Loisirs",IF(Inscriptions!I4="Oui","Football",IF(Inscriptions!J4="Oui","Centre Loisirs","")))) -> Football | F10: =IF(Inscriptions!B4="","",Inscriptions!N4) -> 1750 | G10: =IF(Inscriptions!B4="","",Inscriptions!O4) -> Payé | H10: =IF(Inscriptions!B4="","",IF(Inscriptions!S4="","—",Inscriptions!S4&" j")) -> — | I10: =IF(Inscriptions!B4="","",IF(Inscriptions!O4="Payé","✅ Confirmation",IF(AND(Inscriptions!S4<>"",Inscriptions!S4>0),"🔴 Retard","🟡 Rappel"))) -> ✅ Confirmation | J10: =IF(Inscriptions!B4="","",IF(Inscriptions!O4="Payé",SUBSTITUTE(SUBSTITUTE(SUBSTITUTE(SUBSTITUTE(C5,"{MONTANT}",TEXT(Inscriptions!N4,"#,##0")&" MRU"),"{PRENOM}",Inscriptions!C4),"{NOM}",Inscriptions!B4),"{PRESTATION}",E10),IF(AND(Inscriptions!S4<>"",Inscriptions!S4>0),SUBSTITUTE(SUBSTITUTE(SUBSTITUTE(SUBSTITUTE(C4,"{MONTANT}",TEXT(Inscriptions!N4,"#,##0")&" MRU"),"{PRENOM}",Inscriptions!C4),"{NOM}",Inscriptions!B4),"{RETARD}",TEXT(Inscriptions!S4,"0")),SUBSTITUTE(SUBSTITUTE(SUBSTITUTE(SUBSTITUTE(SUBSTITUTE(C3,"{MONTANT}",TEXT(Inscriptions!N4,"#,##0")&" MRU"),"{PRENOM}",Inscriptions!C4),"{NOM}",Inscriptions!B4),"{PRESTATION}",E10),"{DATE_LIMITE}",IF(Inscriptions!R4="","non définie",TEXT(Inscriptions!R4,"DD/MM/YYYY")))))) -> ✅ Bonjour, la Fiveur Academy confirme la réception du paiement de 1750,0 MRU pour Zackaria SIDIBÉ. Inscription validée pour : Football. Merci de votre confiance ! ⚽ Fiveur Academy — Since 2023.
A11: =IF(Inscriptions!B5="","",Inscriptions!A5) -> 3 | B11: =IF(Inscriptions!B5="","",Inscriptions!B5) -> DIALLO | C11: =IF(Inscriptions!B5="","",Inscriptions!C5) -> Youssouf | D11: =IF(Inscriptions!B5="","",Inscriptions!G5) -> +222 48 44 07 94 | E11: =IF(Inscriptions!B5="","",IF(AND(Inscriptions!I5="Oui",Inscriptions!J5="Oui"),"Football + Loisirs",IF(Inscriptions!I5="Oui","Football",IF(Inscriptions!J5="Oui","Centre Loisirs","")))) -> Football | F11: =IF(Inscriptions!B5="","",Inscriptions!N5) -> 2000 | G11: =IF(Inscriptions!B5="","",Inscriptions!O5) -> Payé | H11: =IF(Inscriptions!B5="","",IF(Inscriptions!S5="","—",Inscriptions!S5&" j")) -> — | I11: =IF(Inscriptions!B5="","",IF(Inscriptions!O5="Payé","✅ Confirmation",IF(AND(Inscriptions!S5<>"",Inscriptions!S5>0),"🔴 Retard","🟡 Rappel"))) -> ✅ Confirmation | J11: =IF(Inscriptions!B5="","",IF(Inscriptions!O5="Payé",SUBSTITUTE(SUBSTITUTE(SUBSTITUTE(SUBSTITUTE(C5,"{MONTANT}",TEXT(Inscriptions!N5,"#,##0")&" MRU"),"{PRENOM}",Inscriptions!C5),"{NOM}",Inscriptions!B5),"{PRESTATION}",E11),IF(AND(Inscriptions!S5<>"",Inscriptions!S5>0),SUBSTITUTE(SUBSTITUTE(SUBSTITUTE(SUBSTITUTE(C4,"{MONTANT}",TEXT(Inscriptions!N5,"#,##0")&" MRU"),"{PRENOM}",Inscriptions!C5),"{NOM}",Inscriptions!B5),"{RETARD}",TEXT(Inscriptions!S5,"0")),SUBSTITUTE(SUBSTITUTE(SUBSTITUTE(SUBSTITUTE(SUBSTITUTE(C3,"{MONTANT}",TEXT(Inscriptions!N5,"#,##0")&" MRU"),"{PRENOM}",Inscriptions!C5),"{NOM}",Inscriptions!B5),"{PRESTATION}",E11),"{DATE_LIMITE}",IF(Inscriptions!R5="","non définie",TEXT(Inscriptions!R5,"DD/MM/YYYY")))))) -> ✅ Bonjour, la Fiveur Academy confirme la réception du paiement de 2000,0 MRU pour Youssouf DIALLO. Inscription validée pour : Football. Merci de votre confiance ! ⚽ Fiveur Academy — Since 2023.
A12: =IF(Inscriptions!B6="","",Inscriptions!A6) -> 4 | B12: =IF(Inscriptions!B6="","",Inscriptions!B6) -> THIAM | C12: =IF(Inscriptions!B6="","",Inscriptions!C6) -> Mohamed | D12: =IF(Inscriptions!B6="","",Inscriptions!G6) -> +222 41 53 98 46 | E12: =IF(Inscriptions!B6="","",IF(AND(Inscriptions!I6="Oui",Inscriptions!J6="Oui"),"Football + Loisirs",IF(Inscriptions!I6="Oui","Football",IF(Inscriptions!J6="Oui","Centre Loisirs","")))) -> Football | F12: =IF(Inscriptions!B6="","",Inscriptions!N6) -> 1000 | G12: =IF(Inscriptions!B6="","",Inscriptions!O6) -> Partiel | H12: =IF(Inscriptions!B6="","",IF(Inscriptions!S6="","—",Inscriptions!S6&" j")) -> 27 j | I12: =IF(Inscriptions!B6="","",IF(Inscriptions!O6="Payé","✅ Confirmation",IF(AND(Inscriptions!S6<>"",Inscriptions!S6>0),"🔴 Retard","🟡 Rappel"))) -> 🔴 Retard | J12: =IF(Inscriptions!B6="","",IF(Inscriptions!O6="Payé",SUBSTITUTE(SUBSTITUTE(SUBSTITUTE(SUBSTITUTE(C5,"{MONTANT}",TEXT(Inscriptions!N6,"#,##0")&" MRU"),"{PRENOM}",Inscriptions!C6),"{NOM}",Inscriptions!B6),"{PRESTATION}",E12),IF(AND(Inscriptions!S6<>"",Inscriptions!S6>0),SUBSTITUTE(SUBSTITUTE(SUBSTITUTE(SUBSTITUTE(C4,"{MONTANT}",TEXT(Inscriptions!N6,"#,##0")&" MRU"),"{PRENOM}",Inscriptions!C6),"{NOM}",Inscriptions!B6),"{RETARD}",TEXT(Inscriptions!S6,"0")),SUBSTITUTE(SUBSTITUTE(SUBSTITUTE(SUBSTITUTE(SUBSTITUTE(C3,"{MONTANT}",TEXT(Inscriptions!N6,"#,##0")&" MRU"),"{PRENOM}",Inscriptions!C6),"{NOM}",Inscriptions!B6),"{PRESTATION}",E12),"{DATE_LIMITE}",IF(Inscriptions!R6="","non définie",TEXT(Inscriptions!R6,"DD/MM/YYYY")))))) -> ⚠️ Bonjour, la Fiveur Academy vous informe que le paiement de 1000,0 MRU pour Mohamed THIAM est en retard de 27 jour(s). Merci de procéder au règlement dans les plus brefs délais pour maintenir l'inscription. Contact : Fiveur Academy.
A13: =IF(Inscriptions!B7="","",Inscriptions!A7) -> 5 | B13: =IF(Inscriptions!B7="","",Inscriptions!B7) -> THIAM | C13: =IF(Inscriptions!B7="","",Inscriptions!C7) -> Adama | D13: =IF(Inscriptions!B7="","",Inscriptions!G7) -> +222 44 89 92 74 | E13: =IF(Inscriptions!B7="","",IF(AND(Inscriptions!I7="Oui",Inscriptions!J7="Oui"),"Football + Loisirs",IF(Inscriptions!I7="Oui","Football",IF(Inscriptions!J7="Oui","Centre Loisirs","")))) -> Football | F13: =IF(Inscriptions!B7="","",Inscriptions!N7) -> 1000 | G13: =IF(Inscriptions!B7="","",Inscriptions!O7) -> Partiel | H13: =IF(Inscriptions!B7="","",IF(Inscriptions!S7="","—",Inscriptions!S7&" j")) -> — | I13: =IF(Inscriptions!B7="","",IF(Inscriptions!O7="Payé","✅ Confirmation",IF(AND(Inscriptions!S7<>"",Inscriptions!S7>0),"🔴 Retard","🟡 Rappel"))) -> 🟡 Rappel | J13: =IF(Inscriptions!B7="","",IF(Inscriptions!O7="Payé",SUBSTITUTE(SUBSTITUTE(SUBSTITUTE(SUBSTITUTE(C5,"{MONTANT}",TEXT(Inscriptions!N7,"#,##0")&" MRU"),"{PRENOM}",Inscriptions!C7),"{NOM}",Inscriptions!B7),"{PRESTATION}",E13),IF(AND(Inscriptions!S7<>"",Inscriptions!S7>0),SUBSTITUTE(SUBSTITUTE(SUBSTITUTE(SUBSTITUTE(C4,"{MONTANT}",TEXT(Inscriptions!N7,"#,##0")&" MRU"),"{PRENOM}",Inscriptions!C7),"{NOM}",Inscriptions!B7),"{RETARD}",TEXT(Inscriptions!S7,"0")),SUBSTITUTE(SUBSTITUTE(SUBSTITUTE(SUBSTITUTE(SUBSTITUTE(C3,"{MONTANT}",TEXT(Inscriptions!N7,"#,##0")&" MRU"),"{PRENOM}",Inscriptions!C7),"{NOM}",Inscriptions!B7),"{PRESTATION}",E13),"{DATE_LIMITE}",IF(Inscriptions!R7="","non définie",TEXT(Inscriptions!R7,"DD/MM/YYYY")))))) -> Bonjour, ceci est un rappel de la Fiveur Academy. Le paiement de 1000,0 MRU pour l'inscription de Adama THIAM (Football) est en attente. Date limite : non définie. Merci de régulariser. Cordialement, Fiveur Academy.
A14: =IF(Inscriptions!B8="","",Inscriptions!A8) -> 6 | B14: =IF(Inscriptions!B8="","",Inscriptions!B8) -> KOITA | C14: =IF(Inscriptions!B8="","",Inscriptions!C8) -> Mohamed | D14: =IF(Inscriptions!B8="","",Inscriptions!G8) -> +222 46 46 65 50 | E14: =IF(Inscriptions!B8="","",IF(AND(Inscriptions!I8="Oui",Inscriptions!J8="Oui"),"Football + Loisirs",IF(Inscriptions!I8="Oui","Football",IF(Inscriptions!J8="Oui","Centre Loisirs","")))) -> Football | F14: =IF(Inscriptions!B8="","",Inscriptions!N8) -> 0 | G14: =IF(Inscriptions!B8="","",Inscriptions!O8) -> Partiel | H14: =IF(Inscriptions!B8="","",IF(Inscriptions!S8="","—",Inscriptions!S8&" j")) -> — | I14: =IF(Inscriptions!B8="","",IF(Inscriptions!O8="Payé","✅ Confirmation",IF(AND(Inscriptions!S8<>"",Inscriptions!S8>0),"🔴 Retard","🟡 Rappel"))) -> 🟡 Rappel | J14: =IF(Inscriptions!B8="","",IF(Inscriptions!O8="Payé",SUBSTITUTE(SUBSTITUTE(SUBSTITUTE(SUBSTITUTE(C5,"{MONTANT}",TEXT(Inscriptions!N8,"#,##0")&" MRU"),"{PRENOM}",Inscriptions!C8),"{NOM}",Inscriptions!B8),"{PRESTATION}",E14),IF(AND(Inscriptions!S8<>"",Inscriptions!S8>0),SUBSTITUTE(SUBSTITUTE(SUBSTITUTE(SUBSTITUTE(C4,"{MONTANT}",TEXT(Inscriptions!N8,"#,##0")&" MRU"),"{PRENOM}",Inscriptions!C8),"{NOM}",Inscriptions!B8),"{RETARD}",TEXT(Inscriptions!S8,"0")),SUBSTITUTE(SUBSTITUTE(SUBSTITUTE(SUBSTITUTE(SUBSTITUTE(C3,"{MONTANT}",TEXT(Inscriptions!N8,"#,##0")&" MRU"),"{PRENOM}",Inscriptions!C8),"{NOM}",Inscriptions!B8),"{PRESTATION}",E14),"{DATE_LIMITE}",IF(Inscriptions!R8="","non définie",TEXT(Inscriptions!R8,"DD/MM/YYYY")))))) -> Bonjour, ceci est un rappel de la Fiveur Academy. Le paiement de ,0 MRU pour l'inscription de Mohamed KOITA (Football) est en attente. Date limite : non définie. Merci de régulariser. Cordialement, Fiveur Academy.
A15: =IF(Inscriptions!B9="","",Inscriptions!A9) -> 7 | B15: =IF(Inscriptions!B9="","",Inscriptions!B9) -> KOITA | C15: =IF(Inscriptions!B9="","",Inscriptions!C9) -> Youba | D15: =IF(Inscriptions!B9="","",Inscriptions!G9) -> +222 46 46 65 50 | E15: =IF(Inscriptions!B9="","",IF(AND(Inscriptions!I9="Oui",Inscriptions!J9="Oui"),"Football + Loisirs",IF(Inscriptions!I9="Oui","Football",IF(Inscriptions!J9="Oui","Centre Loisirs","")))) -> Football | F15: =IF(Inscriptions!B9="","",Inscriptions!N9) -> 0 | G15: =IF(Inscriptions!B9="","",Inscriptions!O9) -> Partiel | H15: =IF(Inscriptions!B9="","",IF(Inscriptions!S9="","—",Inscriptions!S9&" j")) -> — | I15: =IF(Inscriptions!B9="","",IF(Inscriptions!O9="Payé","✅ Confirmation",IF(AND(Inscriptions!S9<>"",Inscriptions!S9>0),"🔴 Retard","🟡 Rappel"))) -> 🟡 Rappel | J15: =IF(Inscriptions!B9="","",IF(Inscriptions!O9="Payé",SUBSTITUTE(SUBSTITUTE(SUBSTITUTE(SUBSTITUTE(C5,"{MONTANT}",TEXT(Inscriptions!N9,"#,##0")&" MRU"),"{PRENOM}",Inscriptions!C9),"{NOM}",Inscriptions!B9),"{PRESTATION}",E15),IF(AND(Inscriptions!S9<>"",Inscriptions!S9>0),SUBSTITUTE(SUBSTITUTE(SUBSTITUTE(SUBSTITUTE(C4,"{MONTANT}",TEXT(Inscriptions!N9,"#,##0")&" MRU"),"{PRENOM}",Inscriptions!C9),"{NOM}",Inscriptions!B9),"{RETARD}",TEXT(Inscriptions!S9,"0")),SUBSTITUTE(SUBSTITUTE(SUBSTITUTE(SUBSTITUTE(SUBSTITUTE(C3,"{MONTANT}",TEXT(Inscriptions!N9,"#,##0")&" MRU"),"{PRENOM}",Inscriptions!C9),"{NOM}",Inscriptions!B9),"{PRESTATION}",E15),"{DATE_LIMITE}",IF(Inscriptions!R9="","non définie",TEXT(Inscriptions!R9,"DD/MM/YYYY")))))) -> Bonjour, ceci est un rappel de la Fiveur Academy. Le paiement de ,0 MRU pour l'inscription de Youba KOITA (Football) est en attente. Date limite : non définie. Merci de régulariser. Cordialement, Fiveur Academy.
A16: =IF(Inscriptions!B10="","",Inscriptions!A10) -> 8 | B16: =IF(Inscriptions!B10="","",Inscriptions!B10) -> THIAM | C16: =IF(Inscriptions!B10="","",Inscriptions!C10) -> Binta | D16: =IF(Inscriptions!B10="","",Inscriptions!G10) -> +222 41 53 98 46 | E16: =IF(Inscriptions!B10="","",IF(AND(Inscriptions!I10="Oui",Inscriptions!J10="Oui"),"Football + Loisirs",IF(Inscriptions!I10="Oui","Football",IF(Inscriptions!J10="Oui","Centre Loisirs","")))) -> Football | F16: =IF(Inscriptions!B10="","",Inscriptions!N10) -> 1000 | G16: =IF(Inscriptions!B10="","",Inscriptions!O10) -> Partiel | H16: =IF(Inscriptions!B10="","",IF(Inscriptions!S10="","—",Inscriptions!S10&" j")) -> — | I16: =IF(Inscriptions!B10="","",IF(Inscriptions!O10="Payé","✅ Confirmation",IF(AND(Inscriptions!S10<>"",Inscriptions!S10>0),"🔴 Retard","🟡 Rappel"))) -> 🟡 Rappel | J16: =IF(Inscriptions!B10="","",IF(Inscriptions!O10="Payé",SUBSTITUTE(SUBSTITUTE(SUBSTITUTE(SUBSTITUTE(C5,"{MONTANT}",TEXT(Inscriptions!N10,"#,##0")&" MRU"),"{PRENOM}",Inscriptions!C10),"{NOM}",Inscriptions!B10),"{PRESTATION}",E16),IF(AND(Inscriptions!S10<>"",Inscriptions!S10>0),SUBSTITUTE(SUBSTITUTE(SUBSTITUTE(SUBSTITUTE(C4,"{MONTANT}",TEXT(Inscriptions!N10,"#,##0")&" MRU"),"{PRENOM}",Inscriptions!C10),"{NOM}",Inscriptions!B10),"{RETARD}",TEXT(Inscriptions!S10,"0")),SUBSTITUTE(SUBSTITUTE(SUBSTITUTE(SUBSTITUTE(SUBSTITUTE(C3,"{MONTANT}",TEXT(Inscriptions!N10,"#,##0")&" MRU"),"{PRENOM}",Inscriptions!C10),"{NOM}",Inscriptions!B10),"{PRESTATION}",E16),"{DATE_LIMITE}",IF(Inscriptions!R10="","non définie",TEXT(Inscriptions!R10,"DD/MM/YYYY")))))) -> Bonjour, ceci est un rappel de la Fiveur Academy. Le paiement de 1000,0 MRU pour l'inscription de Binta THIAM (Football) est en attente. Date limite : non définie. Merci de régulariser. Cordialement, Fiveur Academy.
A17: =IF(Inscriptions!B11="","",Inscriptions!A11) -> 9 | B17: =IF(Inscriptions!B11="","",Inscriptions!B11) -> DIARRA | C17: =IF(Inscriptions!B11="","",Inscriptions!C11) -> Ibrahim | D17: =IF(Inscriptions!B11="","",Inscriptions!G11) -> +222 41 46 24 13 | E17: =IF(Inscriptions!B11="","",IF(AND(Inscriptions!I11="Oui",Inscriptions!J11="Oui"),"Football + Loisirs",IF(Inscriptions!I11="Oui","Football",IF(Inscriptions!J11="Oui","Centre Loisirs","")))) -> Football | F17: =IF(Inscriptions!B11="","",Inscriptions!N11) -> 1000 | G17: =IF(Inscriptions!B11="","",Inscriptions!O11) -> Partiel | H17: =IF(Inscriptions!B11="","",IF(Inscriptions!S11="","—",Inscriptions!S11&" j")) -> — | I17: =IF(Inscriptions!B11="","",IF(Inscriptions!O11="Payé","✅ Confirmation",IF(AND(Inscriptions!S11<>"",Inscriptions!S11>0),"🔴 Retard","🟡 Rappel"))) -> 🟡 Rappel | J17: =IF(Inscriptions!B11="","",IF(Inscriptions!O11="Payé",SUBSTITUTE(SUBSTITUTE(SUBSTITUTE(SUBSTITUTE(C5,"{MONTANT}",TEXT(Inscriptions!N11,"#,##0")&" MRU"),"{PRENOM}",Inscriptions!C11),"{NOM}",Inscriptions!B11),"{PRESTATION}",E17),IF(AND(Inscriptions!S11<>"",Inscriptions!S11>0),SUBSTITUTE(SUBSTITUTE(SUBSTITUTE(SUBSTITUTE(C4,"{MONTANT}",TEXT(Inscriptions!N11,"#,##0")&" MRU"),"{PRENOM}",Inscriptions!C11),"{NOM}",Inscriptions!B11),"{RETARD}",TEXT(Inscriptions!S11,"0")),SUBSTITUTE(SUBSTITUTE(SUBSTITUTE(SUBSTITUTE(SUBSTITUTE(C3,"{MONTANT}",TEXT(Inscriptions!N11,"#,##0")&" MRU"),"{PRENOM}",Inscriptions!C11),"{NOM}",Inscriptions!B11),"{PRESTATION}",E17),"{DATE_LIMITE}",IF(Inscriptions!R11="","non définie",TEXT(Inscriptions!R11,"DD/MM/YYYY")))))) -> Bonjour, ceci est un rappel de la Fiveur Academy. Le paiement de 1000,0 MRU pour l'inscription de Ibrahim DIARRA (Football) est en attente. Date limite : non définie. Merci de régulariser. Cordialement, Fiveur Academy.
A18: =IF(Inscriptions!B12="","",Inscriptions!A12) -> 10 | B18: =IF(Inscriptions!B12="","",Inscriptions!B12) -> BA | C18: =IF(Inscriptions!B12="","",Inscriptions!C12) -> Amadou | D18: =IF(Inscriptions!B12="","",Inscriptions!G12) -> +222 46 33 74 63 | E18: =IF(Inscriptions!B12="","",IF(AND(Inscriptions!I12="Oui",Inscriptions!J12="Oui"),"Football + Loisirs",IF(Inscriptions!I12="Oui","Football",IF(Inscriptions!J12="Oui","Centre Loisirs","")))) -> Football | F18: =IF(Inscriptions!B12="","",Inscriptions!N12) -> 1000 | G18: =IF(Inscriptions!B12="","",Inscriptions!O12) -> Partiel | H18: =IF(Inscriptions!B12="","",IF(Inscriptions!S12="","—",Inscriptions!S12&" j")) -> — | I18: =IF(Inscriptions!B12="","",IF(Inscriptions!O12="Payé","✅ Confirmation",IF(AND(Inscriptions!S12<>"",Inscriptions!S12>0),"🔴 Retard","🟡 Rappel"))) -> 🟡 Rappel | J18: =IF(Inscriptions!B12="","",IF(Inscriptions!O12="Payé",SUBSTITUTE(SUBSTITUTE(SUBSTITUTE(SUBSTITUTE(C5,"{MONTANT}",TEXT(Inscriptions!N12,"#,##0")&" MRU"),"{PRENOM}",Inscriptions!C12),"{NOM}",Inscriptions!B12),"{PRESTATION}",E18),IF(AND(Inscriptions!S12<>"",Inscriptions!S12>0),SUBSTITUTE(SUBSTITUTE(SUBSTITUTE(SUBSTITUTE(C4,"{MONTANT}",TEXT(Inscriptions!N12,"#,##0")&" MRU"),"{PRENOM}",Inscriptions!C12),"{NOM}",Inscriptions!B12),"{RETARD}",TEXT(Inscriptions!S12,"0")),SUBSTITUTE(SUBSTITUTE(SUBSTITUTE(SUBSTITUTE(SUBSTITUTE(C3,"{MONTANT}",TEXT(Inscriptions!N12,"#,##0")&" MRU"),"{PRENOM}",Inscriptions!C12),"{NOM}",Inscriptions!B12),"{PRESTATION}",E18),"{DATE_LIMITE}",IF(Inscriptions!R12="","non définie",TEXT(Inscriptions!R12,"DD/MM/YYYY")))))) -> Bonjour, ceci est un rappel de la Fiveur Academy. Le paiement de 1000,0 MRU pour l'inscription de Amadou BA (Football) est en attente. Date limite : non définie. Merci de régulariser. Cordialement, Fiveur Academy.
A19: =IF(Inscriptions!B13="","",Inscriptions!A13) -> 11 | B19: =IF(Inscriptions!B13="","",Inscriptions!B13) -> SAKHO | C19: =IF(Inscriptions!B13="","",Inscriptions!C13) -> Boubou | D19: =IF(Inscriptions!B13="","",Inscriptions!G13) -> +222 49 07 16 53 | E19: =IF(Inscriptions!B13="","",IF(AND(Inscriptions!I13="Oui",Inscriptions!J13="Oui"),"Football + Loisirs",IF(Inscriptions!I13="Oui","Football",IF(Inscriptions!J13="Oui","Centre Loisirs","")))) -> Football | F19: =IF(Inscriptions!B13="","",Inscriptions!N13) -> 2000 | G19: =IF(Inscriptions!B13="","",Inscriptions!O13) -> Payé | H19: =IF(Inscriptions!B13="","",IF(Inscriptions!S13="","—",Inscriptions!S13&" j")) -> — | I19: =IF(Inscriptions!B13="","",IF(Inscriptions!O13="Payé","✅ Confirmation",IF(AND(Inscriptions!S13<>"",Inscriptions!S13>0),"🔴 Retard","🟡 Rappel"))) -> ✅ Confirmation | J19: =IF(Inscriptions!B13="","",IF(Inscriptions!O13="Payé",SUBSTITUTE(SUBSTITUTE(SUBSTITUTE(SUBSTITUTE(C5,"{MONTANT}",TEXT(Inscriptions!N13,"#,##0")&" MRU"),"{PRENOM}",Inscriptions!C13),"{NOM}",Inscriptions!B13),"{PRESTATION}",E19),IF(AND(Inscriptions!S13<>"",Inscriptions!S13>0),SUBSTITUTE(SUBSTITUTE(SUBSTITUTE(SUBSTITUTE(C4,"{MONTANT}",TEXT(Inscriptions!N13,"#,##0")&" MRU"),"{PRENOM}",Inscriptions!C13),"{NOM}",Inscriptions!B13),"{RETARD}",TEXT(Inscriptions!S13,"0")),SUBSTITUTE(SUBSTITUTE(SUBSTITUTE(SUBSTITUTE(SUBSTITUTE(C3,"{MONTANT}",TEXT(Inscriptions!N13,"#,##0")&" MRU"),"{PRENOM}",Inscriptions!C13),"{NOM}",Inscriptions!B13),"{PRESTATION}",E19),"{DATE_LIMITE}",IF(Inscriptions!R13="","non définie",TEXT(Inscriptions!R13,"DD/MM/YYYY")))))) -> ✅ Bonjour, la Fiveur Academy confirme la réception du paiement de 2000,0 MRU pour Boubou SAKHO . Inscription validée pour : Football. Merci de votre confiance ! ⚽ Fiveur Academy — Since 2023.
A20: =IF(Inscriptions!B14="","",Inscriptions!A14) -> 12 | B20: =IF(Inscriptions!B14="","",Inscriptions!B14) -> DJIGO | C20: =IF(Inscriptions!B14="","",Inscriptions!C14) -> Cheikh bay | D20: =IF(Inscriptions!B14="","",Inscriptions!G14) -> +222 49 47 01 42 | E20: =IF(Inscriptions!B14="","",IF(AND(Inscriptions!I14="Oui",Inscriptions!J14="Oui"),"Football + Loisirs",IF(Inscriptions!I14="Oui","Football",IF(Inscriptions!J14="Oui","Centre Loisirs","")))) -> Football | F20: =IF(Inscriptions!B14="","",Inscriptions!N14) -> 0 | G20: =IF(Inscriptions!B14="","",Inscriptions!O14) -> En attente | H20: =IF(Inscriptions!B14="","",IF(Inscriptions!S14="","—",Inscriptions!S14&" j")) -> " j | I20: =IF(Inscriptions!B14="","",IF(Inscriptions!O14="Payé","✅ Confirmation",IF(AND(Inscriptions!S14<>"",Inscriptions!S14>0),"🔴 Retard","🟡 Rappel"))) -> 🔴 Retard | J20: =IF(Inscriptions!B14="","",IF(Inscriptions!O14="Payé",SUBSTITUTE(SUBSTITUTE(SUBSTITUTE(SUBSTITUTE(C5,"{MONTANT}",TEXT(Inscriptions!N14,"#,##0")&" MRU"),"{PRENOM}",Inscriptions!C14),"{NOM}",Inscriptions!B14),"{PRESTATION}",E20),IF(AND(Inscriptions!S14<>"",Inscriptions!S14>0),SUBSTITUTE(SUBSTITUTE(SUBSTITUTE(SUBSTITUTE(C4,"{MONTANT}",TEXT(Inscriptions!N14,"#,##0")&" MRU"),"{PRENOM}",Inscriptions!C14),"{NOM}",Inscriptions!B14),"{RETARD}",TEXT(Inscriptions!S14,"0")),SUBSTITUTE(SUBSTITUTE(SUBSTITUTE(SUBSTITUTE(SUBSTITUTE(C3,"{MONTANT}",TEXT(Inscriptions!N14,"#,##0")&" MRU"),"{PRENOM}",Inscriptions!C14),"{NOM}",Inscriptions!B14),"{PRESTATION}",E20),"{DATE_LIMITE}",IF(Inscriptions!R14="","non définie",TEXT(Inscriptions!R14,"DD/MM/YYYY")))))) -> ⚠️ Bonjour, la Fiveur Academy vous informe que le paiement de ,0 MRU pour Cheikh bay DJIGO est en retard de " jour(s). Merci de procéder au règlement dans les plus brefs délais pour maintenir l'inscription. Contact : Fiveur Academy.
A21: =IF(Inscriptions!B15="","",Inscriptions!A15) | B21: =IF(Inscriptions!B15="","",Inscriptions!B15) | C21: =IF(Inscriptions!B15="","",Inscriptions!C15) | D21: =IF(Inscriptions!B15="","",Inscriptions!G15) | E21: =IF(Inscriptions!B15="","",IF(AND(Inscriptions!I15="Oui",Inscriptions!J15="Oui"),"Football + Loisirs",IF(Inscriptions!I15="Oui","Football",IF(Inscriptions!J15="Oui","Centre Loisirs","")))) | F21: =IF(Inscriptions!B15="","",Inscriptions!N15) | G21: =IF(Inscriptions!B15="","",Inscriptions!O15) | H21: =IF(Inscriptions!B15="","",IF(Inscriptions!S15="","—",Inscriptions!S15&" j")) | I21: =IF(Inscriptions!B15="","",IF(Inscriptions!O15="Payé","✅ Confirmation",IF(AND(Inscriptions!S15<>"",Inscriptions!S15>0),"🔴 Retard","🟡 Rappel"))) | J21: =IF(Inscriptions!B15="","",IF(Inscriptions!O15="Payé",SUBSTITUTE(SUBSTITUTE(SUBSTITUTE(SUBSTITUTE(C5,"{MONTANT}",TEXT(Inscriptions!N15,"#,##0")&" MRU"),"{PRENOM}",Inscriptions!C15),"{NOM}",Inscriptions!B15),"{PRESTATION}",E21),IF(AND(Inscriptions!S15<>"",Inscriptions!S15>0),SUBSTITUTE(SUBSTITUTE(SUBSTITUTE(SUBSTITUTE(C4,"{MONTANT}",TEXT(Inscriptions!N15,"#,##0")&" MRU"),"{PRENOM}",Inscriptions!C15),"{NOM}",Inscriptions!B15),"{RETARD}",TEXT(Inscriptions!S15,"0")),SUBSTITUTE(SUBSTITUTE(SUBSTITUTE(SUBSTITUTE(SUBSTITUTE(C3,"{MONTANT}",TEXT(Inscriptions!N15,"#,##0")&" MRU"),"{PRENOM}",Inscriptions!C15),"{NOM}",Inscriptions!B15),"{PRESTATION}",E21),"{DATE_LIMITE}",IF(Inscriptions!R15="","non définie",TEXT(Inscriptions!R15,"DD/MM/YYYY"))))))
A22: =IF(Inscriptions!B16="","",Inscriptions!A16) | B22: =IF(Inscriptions!B16="","",Inscriptions!B16) | C22: =IF(Inscriptions!B16="","",Inscriptions!C16) | D22: =IF(Inscriptions!B16="","",Inscriptions!G16) | E22: =IF(Inscriptions!B16="","",IF(AND(Inscriptions!I16="Oui",Inscriptions!J16="Oui"),"Football + Loisirs",IF(Inscriptions!I16="Oui","Football",IF(Inscriptions!J16="Oui","Centre Loisirs","")))) | F22: =IF(Inscriptions!B16="","",Inscriptions!N16) | G22: =IF(Inscriptions!B16="","",Inscriptions!O16) | H22: =IF(Inscriptions!B16="","",IF(Inscriptions!S16="","—",Inscriptions!S16&" j")) | I22: =IF(Inscriptions!B16="","",IF(Inscriptions!O16="Payé","✅ Confirmation",IF(AND(Inscriptions!S16<>"",Inscriptions!S16>0),"🔴 Retard","🟡 Rappel"))) | J22: =IF(Inscriptions!B16="","",IF(Inscriptions!O16="Payé",SUBSTITUTE(SUBSTITUTE(SUBSTITUTE(SUBSTITUTE(C5,"{MONTANT}",TEXT(Inscriptions!N16,"#,##0")&" MRU"),"{PRENOM}",Inscriptions!C16),"{NOM}",Inscriptions!B16),"{PRESTATION}",E22),IF(AND(Inscriptions!S16<>"",Inscriptions!S16>0),SUBSTITUTE(SUBSTITUTE(SUBSTITUTE(SUBSTITUTE(C4,"{MONTANT}",TEXT(Inscriptions!N16,"#,##0")&" MRU"),"{PRENOM}",Inscriptions!C16),"{NOM}",Inscriptions!B16),"{RETARD}",TEXT(Inscriptions!S16,"0")),SUBSTITUTE(SUBSTITUTE(SUBSTITUTE(SUBSTITUTE(SUBSTITUTE(C3,"{MONTANT}",TEXT(Inscriptions!N16,"#,##0")&" MRU"),"{PRENOM}",Inscriptions!C16),"{NOM}",Inscriptions!B16),"{PRESTATION}",E22),"{DATE_LIMITE}",IF(Inscriptions!R16="","non définie",TEXT(Inscriptions!R16,"DD/MM/YYYY"))))))
A23: =IF(Inscriptions!B17="","",Inscriptions!A17) -> 15 | B23: =IF(Inscriptions!B17="","",Inscriptions!B17) -> NBODJ | C23: =IF(Inscriptions!B17="","",Inscriptions!C17) -> Babacar | D23: =IF(Inscriptions!B17="","",Inscriptions!G17) -> +222 44 89 97 98 | E23: =IF(Inscriptions!B17="","",IF(AND(Inscriptions!I17="Oui",Inscriptions!J17="Oui"),"Football + Loisirs",IF(Inscriptions!I17="Oui","Football",IF(Inscriptions!J17="Oui","Centre Loisirs","")))) -> Football | F23: =IF(Inscriptions!B17="","",Inscriptions!N17) -> 2000 | G23: =IF(Inscriptions!B17="","",Inscriptions!O17) -> Payé | H23: =IF(Inscriptions!B17="","",IF(Inscriptions!S17="","—",Inscriptions!S17&" j")) -> — | I23: =IF(Inscriptions!B17="","",IF(Inscriptions!O17="Payé","✅ Confirmation",IF(AND(Inscriptions!S17<>"",Inscriptions!S17>0),"🔴 Retard","🟡 Rappel"))) -> ✅ Confirmation | J23: =IF(Inscriptions!B17="","",IF(Inscriptions!O17="Payé",SUBSTITUTE(SUBSTITUTE(SUBSTITUTE(SUBSTITUTE(C5,"{MONTANT}",TEXT(Inscriptions!N17,"#,##0")&" MRU"),"{PRENOM}",Inscriptions!C17),"{NOM}",Inscriptions!B17),"{PRESTATION}",E23),IF(AND(Inscriptions!S17<>"",Inscriptions!S17>0),SUBSTITUTE(SUBSTITUTE(SUBSTITUTE(SUBSTITUTE(C4,"{MONTANT}",TEXT(Inscriptions!N17,"#,##0")&" MRU"),"{PRENOM}",Inscriptions!C17),"{NOM}",Inscriptions!B17),"{RETARD}",TEXT(Inscriptions!S17,"0")),SUBSTITUTE(SUBSTITUTE(SUBSTITUTE(SUBSTITUTE(SUBSTITUTE(C3,"{MONTANT}",TEXT(Inscriptions!N17,"#,##0")&" MRU"),"{PRENOM}",Inscriptions!C17),"{NOM}",Inscriptions!B17),"{PRESTATION}",E23),"{DATE_LIMITE}",IF(Inscriptions!R17="","non définie",TEXT(Inscriptions!R17,"DD/MM/YYYY")))))) -> ✅ Bonjour, la Fiveur Academy confirme la réception du paiement de 2000,0 MRU pour Babacar NBODJ. Inscription validée pour : Football. Merci de votre confiance ! ⚽ Fiveur Academy — Since 2023.
